#VRML_SIM R2019a utf8
WorldInfo {
}
Viewpoint {
  orientation -0.9911603603175486 0.13117955548892685 0.0198258507236088 0.30263506347201213
  position 0.011868765135311224 0.897859910034591 1.5758643622901511
}
TexturedBackground {
}
TexturedBackgroundLight {
}
Floor {
}
Solid {
  translation 0 0.25 0
  children [
    Shape {
      appearance PBRAppearance {
        baseColor 0 0 1
        roughness 1
        metalness 0
      }
      geometry Cylinder {
        height 0.5
        radius 0.05
      }
    }
    HingeJoint {
      jointParameters HingeJointParameters {
        axis 0 1 0
        anchor 0 0.255 0
        staticFriction 0.1
      }
      endPoint Solid {
        translation 0 0.25467137226753755 0
        children [
          Shape {
            appearance PBRAppearance {
              baseColor 1 0 0
              roughness 1
              metalness 0
            }
            geometry Box {
              size 0.8 0.01 0.1
            }
          }
        ]
        physics Physics {
        }
      }
    }
  ]
}
