#VRML_SIM R2019a utf8
WorldInfo {
}
Viewpoint {
  orientation 1 -2.1940371460130327e-47 1.088606013287018e-40 6.283185059622904
  position 1.185046854670823e-62 0.24999999999999986 1.8967187597315245
}
TexturedBackground {
}
TexturedBackgroundLight {
}
Floor {
}
Solid {
  translation 0 0.25 0
  children [
    Shape {
      appearance PBRAppearance {
        baseColor 0 0 1
        roughness 1
        metalness 0
      }
      geometry Cylinder {
        height 0.5
        radius 0.05
      }
    }
    HingeJoint {
      jointParameters HingeJointParameters {
        axis 0 1 0
        anchor 0 0.255 0
        minStop -0.785
        maxStop 0.785
        staticFriction 0.1
      }
      endPoint Solid {
        translation 0 0.25467137226753755 0
        children [
          Shape {
            appearance PBRAppearance {
              baseColor 1 0 0
              roughness 1
              metalness 0
            }
            geometry Box {
              size 0.8 0.01 0.1
            }
          }
        ]
        physics Physics {
        }
      }
    }
    HingeJoint {
      jointParameters HingeJointParameters {
        axis 0 1 0
      }
      endPoint Solid {
        translation 0 0 0.055
        rotation 0 0 1 0
        children [
          Shape {
            appearance PBRAppearance {
              baseColor 0 1 0
              roughness 1
              metalness 0
            }
            geometry Box {
              size 0.1 0.03 0.01
            }
          }
        ]
        name "solid(1)"
        physics Physics {
        }
      }
    }
  ]
}
